<?xml version="1.0" ?>
<!-- =================================================================================== -->
<!-- |    This document was autogenerated by xacro from ./src/ros2_fanuc_interface/crx_description/urdf/crx10ia_l/crx10ia_l.xacro | -->
<!-- |    EDITING THIS FILE BY HAND IS NOT RECOMMENDED                                 | -->
<!-- =================================================================================== -->
<robot name="crx10ia_l">
  <!-- Read only parameter should allow to move the robot via manual guidance, jog, etc throu the TP, and makes available the /joint_states topic -->
  <ros2_control name="crx10" type="system">
    <hardware>
      <plugin>mock_components/GenericSystem</plugin>
      <!-- <param name="position_state_following_offset">0.1</param> -->
    </hardware>
    <joint name="J1">
      <command_interface name="position">
        <param name="min">{-2*pi}</param>
        <param name="max">{2*pi}</param>
      </command_interface>
      <!-- <command_interface name="velocity">
          <param name="min">-3.15</param>
          <param name="max">3.15</param>
        </command_interface> -->
      <state_interface name="position">
        <param name="initial_value">0.0</param>
      </state_interface>
      <state_interface name="velocity"/>
    </joint>
    <joint name="J2">
      <command_interface name="position">
        <param name="min">{-2*pi}</param>
        <param name="max">{2*pi}</param>
      </command_interface>
      <!-- <command_interface name="velocity">
          <param name="min">-3.15</param>
          <param name="max">3.15</param>
        </command_interface> -->
      <state_interface name="position">
        <param name="initial_value">0.0</param>
      </state_interface>
      <state_interface name="velocity"/>
    </joint>
    <joint name="J3">
      <command_interface name="position">
        <param name="min">{-pi}</param>
        <param name="max">{pi}</param>
      </command_interface>
      <!-- <command_interface name="velocity">
          <param name="min">-3.15</param>
          <param name="max">3.15</param>
        </command_interface> -->
      <state_interface name="position">
        <param name="initial_value">0.0</param>
      </state_interface>
      <state_interface name="velocity"/>
    </joint>
    <joint name="J4">
      <command_interface name="position">
        <param name="min">{-2*pi}</param>
        <param name="max">{2*pi}</param>
      </command_interface>
      <!-- <command_interface name="velocity">
          <param name="min">-3.2</param>
          <param name="max">3.2</param>
        </command_interface> -->
      <state_interface name="position">
        <param name="initial_value">0.0</param>
      </state_interface>
      <state_interface name="velocity"/>
    </joint>
    <joint name="J5">
      <command_interface name="position">
        <param name="min">{-2*pi}</param>
        <param name="max">{2*pi}</param>
      </command_interface>
      <!-- <command_interface name="velocity">
          <param name="min">-3.2</param>
          <param name="max">3.2</param>
        </command_interface> -->
      <state_interface name="position">
        <param name="initial_value">0.0</param>
      </state_interface>
      <state_interface name="velocity"/>
    </joint>
    <joint name="J6">
      <command_interface name="position">
        <param name="min">{-2*pi}</param>
        <param name="max">{2*pi}</param>
      </command_interface>
      <!-- <command_interface name="velocity">
          <param name="min">-3.2</param>
          <param name="max">3.2</param>
        </command_interface> -->
      <state_interface name="position">
        <param name="initial_value">0.0</param>
      </state_interface>
      <state_interface name="velocity"/>
    </joint>
  </ros2_control>
  <material name="FANUC_Black">
    <color rgba="0 0 0 1.0"/>
  </material>
  <material name="FANUC_Yellow">
    <color rgba="1.00 0.84 0.01 1.00"/>
  </material>
  <material name="FANUC_Green">
    <color rgba="0.43 0.68 0.26 1.00"/>
  </material>
  <material name="FANUC_White">
    <color rgba="0.84 0.84 0.82 1.00"/>
  </material>
  <!-- links -->
  <link name="base_link">
    <visual>
      <origin rpy="0 0 0" xyz="0 0 0"/>
      <geometry>
        <mesh filename="package://crx_description/meshes/crx10ia_l/visual/base.stl" scale="0.001 0.001 0.001"/>
      </geometry>
      <material name="FANUC_Black"/>
    </visual>
    <collision>
      <origin rpy="0 0 0" xyz="0 0 0"/>
      <geometry>
        <mesh filename="package://crx_description/meshes/crx10ia_l/collision/base.stl" scale="0.001 0.001 0.001"/>
      </geometry>
    </collision>
    <!--<inertial>
            <mass value="5" />
            <origin xyz="0 0 0" rpy="0 0 0" />
            <inertia ixx="0.004" ixy="0.001" ixz="0" iyy="0.006" iyz="0" izz="0.007" />
      </inertial> -->
    <collision>
      <geometry>
        <box size="0.1 0.1 0.245"/>
      </geometry>
    </collision>
  </link>
  <link name="J1_link">
    <visual>
      <origin rpy="0 0 0" xyz="0 0 -0.11729999999999999"/>
      <geometry>
        <mesh filename="package://crx_description/meshes/crx10ia_l/visual/j1.stl" scale="0.001 0.001 0.001"/>
      </geometry>
      <material name="FANUC_White"/>
    </visual>
    <collision>
      <origin rpy="0 0 0" xyz="0 0 -0.11729999999999999"/>
      <geometry>
        <mesh filename="package://crx_description/meshes/crx10ia_l/collision/j1.stl" scale="0.001 0.001 0.001"/>
      </geometry>
    </collision>
    <!-- <collision>
        <geometry>
          <box size="0.1 0.1 ${mz_1}" />
        </geometry>
      </collision> -->
  </link>
  <link name="J2_link">
    <visual>
      <origin rpy="0 0 0" xyz="-0.0 0 0.0"/>
      <geometry>
        <mesh filename="package://crx_description/meshes/crx10ia_l/visual/j2.stl" scale="0.001 0.001 0.001"/>
      </geometry>
      <material name="FANUC_White"/>
    </visual>
    <collision>
      <origin rpy="0 0 0" xyz="-0.0 0 0.0"/>
      <geometry>
        <mesh filename="package://crx_description/meshes/crx10ia_l/collision/j2.stl" scale="0.001 0.001 0.001"/>
      </geometry>
    </collision>
  </link>
  <link name="J3_link">
    <visual>
      <origin rpy="0 0 0" xyz="-0.0 0 0.0"/>
      <geometry>
        <mesh filename="package://crx_description/meshes/crx10ia_l/visual/j3.stl" scale="0.001 0.001 0.001"/>
      </geometry>
      <material name="FANUC_White"/>
    </visual>
    <collision>
      <origin rpy="0 0 0" xyz="-0.0 0 0.0"/>
      <geometry>
        <mesh filename="package://crx_description/meshes/crx10ia_l/collision/j3.stl" scale="0.001 0.001 0.001"/>
      </geometry>
    </collision>
  </link>
  <link name="J4_link">
    <visual>
      <origin rpy="0 0 0" xyz="0.54 0 0.0"/>
      <geometry>
        <mesh filename="package://crx_description/meshes/crx10ia_l/visual/j4.stl" scale="0.001 0.001 0.001"/>
      </geometry>
      <material name="FANUC_White"/>
    </visual>
    <collision>
      <origin rpy="0 0 0" xyz="0.54 0 0.0"/>
      <geometry>
        <mesh filename="package://crx_description/meshes/crx10ia_l/collision/j4.stl" scale="0.001 0.001 0.001"/>
      </geometry>
    </collision>
  </link>
  <link name="J5_link">
    <visual>
      <origin rpy="0 0 0" xyz="0.0 -0.15 0.0"/>
      <geometry>
        <mesh filename="package://crx_description/meshes/crx10ia_l/visual/j5.stl" scale="0.001 0.001 0.001"/>
      </geometry>
      <material name="FANUC_White"/>
    </visual>
    <collision>
      <origin rpy="0 0 0" xyz="0.0 -0.15 0.0"/>
      <geometry>
        <mesh filename="package://crx_description/meshes/crx10ia_l/collision/j5.stl" scale="0.001 0.001 0.001"/>
      </geometry>
    </collision>
  </link>
  <link name="J6_link">
    <visual>
      <origin rpy="0 0 0" xyz="0.15999999999999992 0.0 0.0"/>
      <geometry>
        <mesh filename="package://crx_description/meshes/crx10ia_l/visual/j6.stl" scale="0.001 0.001 0.001"/>
      </geometry>
      <material name="FANUC_Black"/>
    </visual>
    <collision>
      <origin rpy="0 0 0" xyz="0.15999999999999992 0.0 0.0"/>
      <geometry>
        <mesh filename="package://crx_description/meshes/crx10ia_l/collision/j6.stl" scale="0.001 0.001 0.001"/>
      </geometry>
    </collision>
  </link>
  <!-- joints -->
  <joint name="J1" type="revolute">
    <origin rpy="0 0 0" xyz="0 0 0.245"/>
    <parent link="base_link"/>
    <child link="J1_link"/>
    <axis xyz="0 0 1"/>
    <limit effort="0" lower="-3.139847324337799" upper="3.139847324337799" velocity="2.0943951023931953"/>
  </joint>
  <joint name="J2" type="revolute">
    <origin rpy="0 0 0" xyz="0.0 0 0"/>
    <parent link="J1_link"/>
    <child link="J2_link"/>
    <axis xyz="0 1 0"/>
    <limit effort="0" lower="-3.139847324337799" upper="3.139847324337799" velocity="2.0943951023931953"/>
  </joint>
  <joint name="J3" type="revolute">
    <origin rpy="0 0 0" xyz="0 0 0.71"/>
    <parent link="J2_link"/>
    <child link="J3_link"/>
    <axis xyz="0 -1 0"/>
    <limit effort="0" lower="-4.71238898038469" upper="4.71238898038469" velocity="3.141592653589793"/>
  </joint>
  <joint name="J4" type="revolute">
    <origin rpy="0 0 0" xyz="0 0 0.0"/>
    <parent link="J3_link"/>
    <child link="J4_link"/>
    <axis xyz="-1 0 0"/>
    <limit effort="0" lower="-3.3161255787892263" upper="3.3161255787892263" velocity="3.141592653589793"/>
  </joint>
  <joint name="J5" type="revolute">
    <origin rpy="0 0 0" xyz="0.54 0 0"/>
    <parent link="J4_link"/>
    <child link="J5_link"/>
    <axis xyz="0 -1 0"/>
    <limit effort="0" lower="-3.139847324337799" upper="3.139847324337799" velocity="3.141592653589793"/>
  </joint>
  <joint name="J6" type="revolute">
    <origin rpy="0 0 0" xyz="0 -0.15 0"/>
    <parent link="J5_link"/>
    <child link="J6_link"/>
    <axis xyz="-1 0 0"/>
    <limit effort="0" lower="-3.9269908169872414" upper="3.9269908169872414" velocity="3.141592653589793"/>
  </joint>
  <!-- world coords -->
  <link name="wbase"/>
  <joint name="base_link-wbase" type="fixed">
    <origin rpy="0 0 0" xyz="0 0 0.245"/>
    <parent link="base_link"/>
    <child link="wbase"/>
  </joint>
  <!-- flange coords -->
  <link name="flange"/>
  <joint name="J6-flange" type="fixed">
    <origin rpy="0 0 0" xyz="0.16 0 0"/>
    <parent link="J6_link"/>
    <child link="flange"/>
  </joint>
  <!-- flange1 coords -->
  <link name="flange1"/>
  <joint name="flange-flange1" type="fixed">
    <origin rpy="0 1.5707963267948966 0" xyz="0 0 0"/>
    <parent link="flange"/>
    <child link="flange1"/>
  </joint>
  <!-- tcp coords -->
  <link name="tcp"/>
  <joint name="flange1-tcp" type="fixed">
    <origin rpy="0 0 0" xyz="0 0 0"/>
    <parent link="flange1"/>
    <child link="tcp"/>
  </joint>
  <!-- tcp right coord -->
  <link name="tcp_right"/>
  <joint name="tcp-tcp_right" type="fixed">
    <origin rpy="0 0 0" xyz="0 0.012 0.013"/>
    <parent link="tcp"/>
    <child link="tcp_right"/>
  </joint>
  <!-- tcp left coord -->
  <link name="tcp_left"/>
  <joint name="tcp-tcp_left" type="fixed">
    <origin rpy="0 0 0" xyz="0 -0.012 0.013"/>
    <parent link="tcp"/>
    <child link="tcp_left"/>
  </joint>
</robot>
